Workbook

Sheet BSNC (2)
A1: # | B1: Company | C1: Source | D1: Type | E1: Waiver Code | F1: Previous Waiver code | G1: Name of vulnerable asset | H1: Internal Identification Code | I1: Identification Code External | J1: Vulnerability description | K1: CWE Category | L1: State | M1: Criticity | N1: CVSS / Vendor Severity | O1: Code CVE (Common Vulnerabilities and Exposures) | P1: IP | Q1: Hostname | R1: Port | S1: Port Type | T1: Reported Date | U1: Days that reported | V1: Expiration day according to SLA | W1: SLA State | X1: Waiver | Y1: Date of application for Waiver | Z1: End date of Waiver | AA1: Remediation Date | AB1: Details | AC1: Recommendation | AD1: Risks Derived | AE1: Date of attention | AF1: Commentary | AG1: Owner
A2: 1 | B2: BSNC | C2: Deloitte | D2: Wep App | E2: BSNC-2019-021 | F2: BSNC-2019-005 BSNC-2019-007 | G2: Web de Proveedores | H2: MAN-b00ec668 | I2: CO-001-003 | J2: Vulnerabilidad de directorio transversal | L2: Dismissed | M2: Critical | N2: 7.6999998 | P2: 170.169.33.48 | Q2: confirming.santander.com.co | R2: 443 | T2: 42941 | U2: =TODAY()-T2 -> 3268 | V2: =IF(M2="Critical",T2+10,IF(M2="High",T2+30,IF(M2="Bad",T2+30,IF(M2="Medium",T2+90,IF(M2="Warm",T2+90,IF(M2="Low",T2+120,IF(M2="Fair",T2+120,IF(M2="Neutral",T2+120,"")))))))) -> 42951 | W2: =IF(M2="Critical",IF(U2>10,"SLA Vencido","En SLA"),IF(M2="High",IF(U2>30,"SLA Vencido","En SLA"),IF(M2="Bad",IF(U2>30,"SLA Vencido","En SLA"),IF(M2="Medium",IF(U2>90,"SLA Vencido","En SLA"),IF(M2="Warm",IF(U2>90,"SLA Vencido","En SLA"),IF(M2="Low",IF(U2>120,"SLA Vencido","En SLA"),IF(M2="Fair",IF(U2>120,"SLA Vencido","En SLA"),IF(M2="Neutral",IF(U2>120,"SLA Vencido","En SLA"),"Error")))))))) -> SLA Vencido | X2: Waiver | Y2: 1ª Fecha: 25/07/2017 2ª Fecha: 31/07/2019 3ª Fecha: 21/12/2019 4ª Fecha: 13/04/2020 | Z2: 1ª Fecha: 31/07/2019 2ª Fecha: 29/11/2019 3ª Fecha: 30/04/2020 4ª Fecha: 30/06/2020 | AA2: 44025 | AD2: Un directorio transversal (o path traversal) consiste en explotar una vulnerabilidad informática que ocurre cuando no existe suficiente seguridad en cuanto a la validación de un usuario, permitiéndole acceder a cualquier tipo de directorio superior (padre) sin ningún control. | AE2: 44012 | AF2: Fue dado de baja el Lunes 13 de Julio del 2020 | AH2: =IFERROR(VLOOKUP(H2,hoja1!A:A,1,),"N/A") -> N/A
A3: 2 | B3: BSNC | C3: Deloitte | D3: Wep App | E3: BSNC-2019-022 | F3: BSNC-2019-008 | G3: Web de Proveedores | H3: MAN-b00ec669 | I3: CO-005-002 | J3: Cross Site Request Forgery | L3: Dismissed | M3: Critical | N3: 7.5999999 | P3: 170.169.33.48 | Q3: confirming.santander.com.co | R3: 443 | T3: 42941 | U3: =TODAY()-T3 -> 3268 | V3: =IF(M3="Critical",T3+10,IF(M3="High",T3+30,IF(M3="Bad",T3+30,IF(M3="Medium",T3+90,IF(M3="Warm",T3+90,IF(M3="Low",T3+120,IF(M3="Fair",T3+120,IF(M3="Neutral",T3+120,"")))))))) -> 42951 | W3: =IF(M3="Critical",IF(U3>10,"SLA Vencido","En SLA"),IF(M3="High",IF(U3>30,"SLA Vencido","En SLA"),IF(M3="Bad",IF(U3>30,"SLA Vencido","En SLA"),IF(M3="Medium",IF(U3>90,"SLA Vencido","En SLA"),IF(M3="Warm",IF(U3>90,"SLA Vencido","En SLA"),IF(M3="Low",IF(U3>120,"SLA Vencido","En SLA"),IF(M3="Fair",IF(U3>120,"SLA Vencido","En SLA"),IF(M3="Neutral",IF(U3>120,"SLA Vencido","En SLA"),"Error")))))))) -> SLA Vencido | X3: Waiver | Y3: 1ª Fecha: 23/07/2019 2ª Fecha: 21/12/2019 3ª Fecha: 13/04/2020 | Z3: 1ª Fecha: 29/11/2019 2ª Fecha: 30/04/2020 3ª Fecha: 30/06/2020 | AA3: 44025 | AD3: Los ataques de tipo "Cross-site Request Forgery" fuerzan a un usuario a realizar acciones no deseadas en aplicativos web, aprovechando que los usuarios legítimos se encuentran previamente autenticados en la plataforma. De esta manera, un atacante malintencionado podría confeccionar peticiones HTTP que realizasen alguna acción concreta de la aplicación, por ejemplo, cambiar la contraseña del usuario legítimo, hacer una transacción bancaria, etc. Una vez confeccionadas estas peticiones se forzaría al usuario a realizarlas, en este paso interviene un componente de ingeniería social, ya que se ha de hacer llegar al usuario un link con la acción confeccionada por el atacante para que el usuario la ejecute. Por ejemplo, simular una campaña de publicidad de la compañía via e-mail con un enlace a la acción confeccionada por el atacante. Por otro lado, para camuflar el enlace se puede esconder el mismo modificando el texto del hipervínculo, el típico "pulse aquí" o, incluso, utilizar acortadores de URL. De esta manera, cuando el usuario acceda al enlace enviado por correo electrónico se intentará ejecutar la acción deseada dentro de la sesión del usuario en la aplicación, sin que éste se de cuenta. En numerosas ocasiones, si el usuario no se encuentra previamente autenticado, al intentar realizar una acción privilegiada como cambiar la contraseña, el propio aplicativo web presentará al usuario el formulario de inicio de sesión para que éste se autentique y posteriormente realizar la acción diseñada por el atacante. | AE3: 44012 | AF3: Fue dado de baja el Lunes 13 de Julio del 2020 | AH3: =IFERROR(VLOOKUP(H3,hoja1!A:A,1,),"N/A") -> N/A
A4: 3 | B4: BSNC | C4: Deloitte | D4: Wep App | E4: BSNC-2019-013 | G4: Web de Proveedores | H4: MAN-28ad454c | I4: CO-017-002 | J4: Debilidad en el mecanismo de CAPTCHA | L4: Dismissed | M4: Medium | N4: 6.5 | P4: 170.169.33.48 | Q4: confirming.santander.com.co | R4: 443 | T4: 42746 | U4: =TODAY()-T4 -> 3463 | V4: =IF(M4="Critical",T4+10,IF(M4="High",T4+30,IF(M4="Bad",T4+30,IF(M4="Medium",T4+90,IF(M4="Warm",T4+90,IF(M4="Low",T4+120,IF(M4="Fair",T4+120,IF(M4="Neutral",T4+120,"")))))))) -> 42836 | W4: =IF(M4="Critical",IF(U4>10,"SLA Vencido","En SLA"),IF(M4="High",IF(U4>30,"SLA Vencido","En SLA"),IF(M4="Bad",IF(U4>30,"SLA Vencido","En SLA"),IF(M4="Medium",IF(U4>90,"SLA Vencido","En SLA"),IF(M4="Warm",IF(U4>90,"SLA Vencido","En SLA"),IF(M4="Low",IF(U4>120,"SLA Vencido","En SLA"),IF(M4="Fair",IF(U4>120,"SLA Vencido","En SLA"),IF(M4="Neutral",IF(U4>120,"SLA Vencido","En SLA"),"Error")))))))) -> SLA Vencido | X4: Waiver | Y4: 1ª Fecha: 21/12/2019 2ª Fecha: 13/04/2020 | Z4: 1ª Fecha: 30/04/2020 2ª Fecha: 30/06/2020 | AA4: 44025 | AD4: Ataque de fuerza bruta | AE4: 44012 | AF4: Fue dado de baja el Lunes 13 de Julio del 2020 | AH4: =IFERROR(VLOOKUP(H4,hoja1!A:A,1,),"N/A") -> N/A
A5: 4 | B5: BSNC | C5: Deloitte | D5: Wep App | E5: BSNC-2019-023 | G5: Web de Proveedores | H5: MAN-18af2324 | I5: CO-19-AUTO-02-CO-001 | J5: Uso de librerias desactualizadas | L5: Dismissed | M5: Medium | N5: 5.5999999 | P5: 170.169.33.48 | Q5: confirming.santander.com.co | R5: 443 | T5: 43719 | U5: =TODAY()-T5 -> 2490 | V5: =IF(M5="Critical",T5+10,IF(M5="High",T5+30,IF(M5="Bad",T5+30,IF(M5="Medium",T5+90,IF(M5="Warm",T5+90,IF(M5="Low",T5+120,IF(M5="Fair",T5+120,IF(M5="Neutral",T5+120,"")))))))) -> 43809 | W5: =IF(M5="Critical",IF(U5>10,"SLA Vencido","En SLA"),IF(M5="High",IF(U5>30,"SLA Vencido","En SLA"),IF(M5="Bad",IF(U5>30,"SLA Vencido","En SLA"),IF(M5="Medium",IF(U5>90,"SLA Vencido","En SLA"),IF(M5="Warm",IF(U5>90,"SLA Vencido","En SLA"),IF(M5="Low",IF(U5>120,"SLA Vencido","En SLA"),IF(M5="Fair",IF(U5>120,"SLA Vencido","En SLA"),IF(M5="Neutral",IF(U5>120,"SLA Vencido","En SLA"),"Error")))))))) -> SLA Vencido | X5: Waiver | Y5: 1ª Fecha: 21/12/2019 2ª Fecha: 13/04/2020 | Z5: 1ª Fecha: 30/04/2020 2ª Fecha: 30/06/2020 | AA5: 44025 | AB5: Se encuentra el uso de funciones de Modernizr 2.6.2: /WebProveedoresNala/proveedores/js/vendor/modernizr-2.6.2.min.js | AC5: Se recomienda utilizar versiones actualizadas del software y/o plataformas tecnológicas utilizadas, en caso de no ser posible aplicar todas las actualizaciones de seguridad publicadas para la versión utilizada. | AD5: El software o plataforma utilizada no se encuentra actualizado a la última versión disponible. Esto implica que podría ser susceptible de poder ser comprometido mediante vulnerabilidades conocidas que pudieran poner en riesgo el activo afectado. | AE5: 44012 | AF5: Fue dado de baja el Lunes 13 de Julio del 2020 | AH5: =IFERROR(VLOOKUP(H5,hoja1!A:A,1,),"N/A") -> N/A
A6: 5 | B6: BSNC | C6: Deloitte | D6: Wep App | E6: BSNC-2019-014 | G6: Web de Proveedores | H6: MAN-28ad454d | I6: CO-037-001 | J6: Revelación de información a través de SSL/TLS (BEAST) | L6: Dismissed | M6: Medium | N6: 5.3000002 | P6: 170.169.33.48 | Q6: confirming.santander.com.co | R6: 443 | T6: 42879 | U6: =TODAY()-T6 -> 3330 | V6: =IF(M6="Critical",T6+10,IF(M6="High",T6+30,IF(M6="Bad",T6+30,IF(M6="Medium",T6+90,IF(M6="Warm",T6+90,IF(M6="Low",T6+120,IF(M6="Fair",T6+120,IF(M6="Neutral",T6+120,"")))))))) -> 42969 | W6: =IF(M6="Critical",IF(U6>10,"SLA Vencido","En SLA"),IF(M6="High",IF(U6>30,"SLA Vencido","En SLA"),IF(M6="Bad",IF(U6>30,"SLA Vencido","En SLA"),IF(M6="Medium",IF(U6>90,"SLA Vencido","En SLA"),IF(M6="Warm",IF(U6>90,"SLA Vencido","En SLA"),IF(M6="Low",IF(U6>120,"SLA Vencido","En SLA"),IF(M6="Fair",IF(U6>120,"SLA Vencido","En SLA"),IF(M6="Neutral",IF(U6>120,"SLA Vencido","En SLA"),"Error")))))))) -> SLA Vencido | X6: Waiver | Y6: 1ª Fecha: 21/12/2019 2ª Fecha: 13/04/2020 | Z6: 1ª Fecha: 30/04/2020 2ª Fecha: 30/06/2020 | AA6: 44025 | AD6: Existe un fallo de diseño en los protocolos SSL 3.0 y TLS 1.0 al utilizar cifrado de bloque en modo CBC. Esto podría ser utilizado por un atacante remoto para revelar información sensible a través de ataques Man in The Middle. | AE6: 44012 | AF6: Fue dado de baja el Lunes 13 de Julio del 2020 | AH6: =IFERROR(VLOOKUP(H6,hoja1!A:A,1,),"N/A") -> N/A
A7: 6 | B7: BSNC | C7: Deloitte | D7: Wep App | E7: BSNC-2019-012 | G7: Web de Proveedores | H7: MAN-7446a64b | I7: CO-009-008 | J7: Fuga de información de servidor y versión | L7: Dismissed | M7: Medium | N7: 5.3000002 | P7: 170.169.33.48 | Q7: confirming.santander.com.co | R7: 443 | T7: 43207 | U7: =TODAY()-T7 -> 3002 | V7: =IF(M7="Critical",T7+10,IF(M7="High",T7+30,IF(M7="Bad",T7+30,IF(M7="Medium",T7+90,IF(M7="Warm",T7+90,IF(M7="Low",T7+120,IF(M7="Fair",T7+120,IF(M7="Neutral",T7+120,"")))))))) -> 43297 | W7: =IF(M7="Critical",IF(U7>10,"SLA Vencido","En SLA"),IF(M7="High",IF(U7>30,"SLA Vencido","En SLA"),IF(M7="Bad",IF(U7>30,"SLA Vencido","En SLA"),IF(M7="Medium",IF(U7>90,"SLA Vencido","En SLA"),IF(M7="Warm",IF(U7>90,"SLA Vencido","En SLA"),IF(M7="Low",IF(U7>120,"SLA Vencido","En SLA"),IF(M7="Fair",IF(U7>120,"SLA Vencido","En SLA"),IF(M7="Neutral",IF(U7>120,"SLA Vencido","En SLA"),"Error")))))))) -> SLA Vencido | X7: Waiver | Y7: 1ª Fecha: 21/12/2019 2ª Fecha: 13/04/2020 | Z7: 1ª Fecha: 30/04/2020 2ª Fecha: 30/06/2020 | AA7: 44025 | AB7: Durante la realización de las pruebas se ha detectado que en las respuestas del servidor se muestra información sobre el tipo de servidor donde se aloja la aplicación | AC7: Se recomienda evitar que la aplicación devuelva al usuario información relativa a la estructura interna de la misma, así como de las tecnologías utilizadas para el desarrollo de la misma o de la infraestructura que la sustenta. Este tipo de información puede ser accesible a través de las cabeceras de respuesta de la aplicación, mensajes de error y/o páginas por defecto. | AD7: Se ha detectado que la aplicación devuelve información acerca de las tecnologías utilizadas para desarrollar la aplicación y/o de la infraestructura utilizada para sustentar la misma. Esta información podría ser utilizada por un atacante con el objetivo de recabar información para ataques futuros. | AE7: 44012 | AF7: Fue dado de baja el Lunes 13 de Julio del 2020 | AH7: =IFERROR(VLOOKUP(H7,hoja1!A:A,1,),"N/A") -> N/A
A8: 7 | B8: BSNC | C8: Deloitte | D8: Wep App | E8: BSNC-2019-011 | G8: Web de Proveedores | H8: MAN-28ad4540 | I8: CO-004-001 | J8: Divulgación de información httpOnly Cookie en el Servidor Apache HTTP | L8: Dismissed | M8: Medium | N8: 5.3000002 | P8: 170.169.33.48 | Q8: confirming.santander.com.co | R8: 443 | T8: 42608 | U8: =TODAY()-T8 -> 3601 | V8: =IF(M8="Critical",T8+10,IF(M8="High",T8+30,IF(M8="Bad",T8+30,IF(M8="Medium",T8+90,IF(M8="Warm",T8+90,IF(M8="Low",T8+120,IF(M8="Fair",T8+120,IF(M8="Neutral",T8+120,"")))))))) -> 42698 | W8: =IF(M8="Critical",IF(U8>10,"SLA Vencido","En SLA"),IF(M8="High",IF(U8>30,"SLA Vencido","En SLA"),IF(M8="Bad",IF(U8>30,"SLA Vencido","En SLA"),IF(M8="Medium",IF(U8>90,"SLA Vencido","En SLA"),IF(M8="Warm",IF(U8>90,"SLA Vencido","En SLA"),IF(M8="Low",IF(U8>120,"SLA Vencido","En SLA"),IF(M8="Fair",IF(U8>120,"SLA Vencido","En SLA"),IF(M8="Neutral",IF(U8>120,"SLA Vencido","En SLA"),"Error")))))))) -> SLA Vencido | X8: Waiver | Y8: 1ª Fecha: 21/12/2019 2ª Fecha: 13/04/2020 | Z8: 1ª Fecha: 30/04/2020 2ª Fecha: 30/06/2020 | AA8: 44025 | AD8: La exposición de información acerca de las funcionalidades o rutas internas de la aplicación puede implicar a un atacante obtener una mayor comprensión del sistema en uso y, potencialmente, desarrollar más ataques para apuntar a la aplicación web. | AE8: 44012 | AF8: Fue dado de baja el Lunes 13 de Julio del 2020 | AH8: =IFERROR(VLOOKUP(H8,hoja1!A:A,1,),"N/A") -> N/A
A9: 8 | B9: BSNC | C9: Deloitte | D9: Wep App | E9: Wep App | G9: Web de Proveedores | H9: MAN-cc489697 | I9: CO-19-AUTO-01-CO-001 | J9: Uso de Software desactualizado | L9: Dismissed | M9: Medium | N9: 5.3000002 | P9: 170.169.33.48 | Q9: confirming.santander.com.co | R9: 443 | T9: 43580 | U9: =TODAY()-T9 -> 2629 | V9: =IF(M9="Critical",T9+10,IF(M9="High",T9+30,IF(M9="Bad",T9+30,IF(M9="Medium",T9+90,IF(M9="Warm",T9+90,IF(M9="Low",T9+120,IF(M9="Fair",T9+120,IF(M9="Neutral",T9+120,"")))))))) -> 43670 | W9: =IF(M9="Critical",IF(U9>10,"SLA Vencido","En SLA"),IF(M9="High",IF(U9>30,"SLA Vencido","En SLA"),IF(M9="Bad",IF(U9>30,"SLA Vencido","En SLA"),IF(M9="Medium",IF(U9>90,"SLA Vencido","En SLA"),IF(M9="Warm",IF(U9>90,"SLA Vencido","En SLA"),IF(M9="Low",IF(U9>120,"SLA Vencido","En SLA"),IF(M9="Fair",IF(U9>120,"SLA Vencido","En SLA"),IF(M9="Neutral",IF(U9>120,"SLA Vencido","En SLA"),"Error")))))))) -> SLA Vencido | X9: Waiver | Y9: 1ª Fecha: 21/12/2019 2ª Fecha: 13/04/2020 | Z9: 1ª Fecha: 30/04/2020 2ª Fecha: 30/06/2020 | AA9: 44025 | AB9: Las librerias Javascript utilizadas se encuentran desactualizadas. [+]Request: GET https://confirming.santander.com.co /WebProveedoresNala/common/js/prototype.js HTTP/1.1 Pragma: no-cache Cache-Control: no-cache Referer: https://confirming.santander.com.co/WebProveedoresNala/WebPipe Acunetix-Aspect: enabled Acunetix-Aspect-Password: 082119f75623eb7abd7bf357698ff66c Acunetix-Aspect-Queries: filelist;aspectalerts Host: confirming.santander.com.co Connection: Keep-alive Accept-Encoding: gzip,deflate User-Agent: Mozilla/5.0 (Windows NT 6.1; WOW64) AppleWebKit/537.36 (KHTML, like Gecko) Chrome/28.0.1500.63 Safari/537.36 Accept: */* [+]Response: HTTP/1.1 200 OK Date: Fri, 22 Mar 2019 07:12:48 GMT Server: Apache Strict-Transport-Security: max-age=63072000; includeSubdomains; X-Frame-Options: SAMEORIGIN X-XSS-Protection: 1; mode=block Last-Modified: Tue, 14 Oct 2014 17:19:04 GMT Content-Length: 124136 Keep-Alive: timeout=10, max=185 Connection: Keep-Alive Content-Type: application/x-javascript Content-Language: en-US /* Prototype JavaScript framework, version 1.6.0 * (c) 2005-2007 Sam Stephenson * * Prototype is freely distributable under the terms of an MIT-style license. * For details, see the Prototype web site: http://www.prototypejs.org/ * *--------------------------------------------------------------------------*/ | AC9: Se recomienda utilizar versiones actualizadas del software y/o plataformas tecnológicas utilizadas, en caso de no ser posible aplicar todas las actualizaciones de seguridad publicadas para la versión utilizada. | AD9: El software o plataforma utilizada no se encuentra actualizado a la última versión disponible. Esto implica que podría ser susceptible de poder ser comprometido mediante vulnerabilidades conocidas que pudieran poner en riesgo el activo afectado. | AE9: 44012 | AF9: Fue dado de baja el Lunes 13 de Julio del 2020 | AH9: =IFERROR(VLOOKUP(H9,hoja1!A:A,1,),"N/A") -> N/A
A10: 9 | B10: BSNC | C10: Deloitte | D10: Wep App | E10: BSNC-2019-017 | G10: Web de Proveedores | H10: MAN-73a2e320 | I10: CO-19-MANU-01-AP-002 | J10: Uso de cifrado 3DES | L10: Dismissed | M10: Medium | N10: 4.3000002 | P10: 170.169.33.48 | Q10: confirming.santander.com.co | T10: 43609 | U10: =TODAY()-T10 -> 2600 | V10: =IF(M10="Critical",T10+10,IF(M10="High",T10+30,IF(M10="Bad",T10+30,IF(M10="Medium",T10+90,IF(M10="Warm",T10+90,IF(M10="Low",T10+120,IF(M10="Fair",T10+120,IF(M10="Neutral",T10+120,"")))))))) -> 43699 | W10: =IF(M10="Critical",IF(U10>10,"SLA Vencido","En SLA"),IF(M10="High",IF(U10>30,"SLA Vencido","En SLA"),IF(M10="Bad",IF(U10>30,"SLA Vencido","En SLA"),IF(M10="Medium",IF(U10>90,"SLA Vencido","En SLA"),IF(M10="Warm",IF(U10>90,"SLA Vencido","En SLA"),IF(M10="Low",IF(U10>120,"SLA Vencido","En SLA"),IF(M10="Fair",IF(U10>120,"SLA Vencido","En SLA"),IF(M10="Neutral",IF(U10>120,"SLA Vencido","En SLA"),"Error")))))))) -> SLA Vencido | X10: Waiver | Y10: 1ª Fecha: 21/12/2019 2ª Fecha: 13/04/2020 | Z10: 1ª Fecha: 30/04/2020 2ª Fecha: 30/06/2020 | AA10: 44025 | AB10: El activo "confirming.santander.com" permite el uso del algoritmo de cifrado 3DES | AC10: Se recomienda deshabilitar el uso del algoritmo de cifrado 3DES y reconfigurar el servicio afectado para restringir los métodos de cifrado a aquellos que ofrezcan un nivel de seguridad alto. | AD10: El host analizado permite el uso de cifrados SSL de seguridad media basados en el algoritmo de cifrado 3DES. Este algoritmo de cifrado es vulnerable a un ataque conocido como Sweet32. Debido a que 3DES tiene un tamaño de bloque de 64 bits, existe una alta probabilidad de que, dados los bloques 2^32, se encuentren dos bloques que colisionen. Una vez que se ha encontrado una colisión entre dos bloques en texto cifrado, se puede averiguar cómo se relacionan los bloques en texto plano correspondientes. Este conocimiento combinado con varios otros atributos permite el descifrado del texto cifrado. | AE10: 44012 | AF10: Fue dado de baja el Lunes 13 de Julio del 2020 | AH10: =IFERROR(VLOOKUP(H10,hoja1!A:A,1,),"N/A") -> N/A
A11: 10 | B11: BSNC | C11: Deloitte | D11: Wep App | E11: BSNC-2019-019 | G11: Web de Proveedores | H11: MAN-73a2e322 | I11: CO-19-MANU-01-CO-004 | J11: Módulo SSL/TLS Diffie-Hellman < = 1024 Bits (LogJam) | L11: Dismissed | M11: Medium | N11: 4 | P11: 170.169.33.48 | Q11: confirming.santander.com.co | T11: 43609 | U11: =TODAY()-T11 -> 2600 | V11: =IF(M11="Critical",T11+10,IF(M11="High",T11+30,IF(M11="Bad",T11+30,IF(M11="Medium",T11+90,IF(M11="Warm",T11+90,IF(M11="Low",T11+120,IF(M11="Fair",T11+120,IF(M11="Neutral",T11+120,"")))))))) -> 43699 | W11: =IF(M11="Critical",IF(U11>10,"SLA Vencido","En SLA"),IF(M11="High",IF(U11>30,"SLA Vencido","En SLA"),IF(M11="Bad",IF(U11>30,"SLA Vencido","En SLA"),IF(M11="Medium",IF(U11>90,"SLA Vencido","En SLA"),IF(M11="Warm",IF(U11>90,"SLA Vencido","En SLA"),IF(M11="Low",IF(U11>120,"SLA Vencido","En SLA"),IF(M11="Fair",IF(U11>120,"SLA Vencido","En SLA"),IF(M11="Neutral",IF(U11>120,"SLA Vencido","En SLA"),"Error")))))))) -> SLA Vencido | X11: Waiver | Y11: 1ª Fecha: 21/12/2019 2ª Fecha: 13/04/2020 | Z11: 1ª Fecha: 30/04/2020 2ª Fecha: 30/06/2020 | AA11: 44025 | AB11: El activo "confirming.santander.com.co" es vulnerable a LogJam | AC11: Se recomienda configurar el servicio para usar un único módulo de Diffie-Hellman de 2048 bits o mayor. | AD11: El servidor permite conexiones SSL/TLS con uno o más modulos Diffie-Hellman menor o igual a 1024 bits. A través de Criptoanálisis, un usuario malintencionado podría ser capaz de encontrar la clave compartida en un corto periodo de tiempo (dependiendo del tamaño del módulo y de los recursos del atacante). Esto podría permitir al atacante recupera la información en texto plano o violar la integridad de las conexiones. | AE11: 44012 | AF11: Fue dado de baja el Lunes 13 de Julio del 2020 | AH11: =IFERROR(VLOOKUP(H11,hoja1!A:A,1,),"N/A") -> N/A
A12: 11 | B12: BSNC | C12: Deloitte | D12: Wep App | E12: BSNC-2019-015 | G12: Web de Proveedores | H12: MAN-a6e6676b | I12: CO-174-001 | J12: Activo vulnerable a Lucky13 (CVE-2013-0169) | L12: Dismissed | M12: Low | N12: 3.7 | O12: CVE-2013-0169 | P12: 170.169.33.48 | Q12: confirming.santander.com.co | R12: 443 | T12: 43207 | U12: =TODAY()-T12 -> 3002 | V12: =IF(M12="Critical",T12+10,IF(M12="High",T12+30,IF(M12="Bad",T12+30,IF(M12="Medium",T12+90,IF(M12="Warm",T12+90,IF(M12="Low",T12+120,IF(M12="Fair",T12+120,IF(M12="Neutral",T12+120,"")))))))) -> 43327 | W12: =IF(M12="Critical",IF(U12>10,"SLA Vencido","En SLA"),IF(M12="High",IF(U12>30,"SLA Vencido","En SLA"),IF(M12="Bad",IF(U12>30,"SLA Vencido","En SLA"),IF(M12="Medium",IF(U12>90,"SLA Vencido","En SLA"),IF(M12="Warm",IF(U12>90,"SLA Vencido","En SLA"),IF(M12="Low",IF(U12>120,"SLA Vencido","En SLA"),IF(M12="Fair",IF(U12>120,"SLA Vencido","En SLA"),IF(M12="Neutral",IF(U12>120,"SLA Vencido","En SLA"),"Error")))))))) -> SLA Vencido | X12: Waiver | Y12: 1ª Fecha: 21/12/2019 2ª Fecha: 13/04/2020 | Z12: 1ª Fecha: 30/04/2020 2ª Fecha: 30/06/2020 | AA12: 44025 | AB12: se ha detectado que el certificado del servidor (www.santander.com.co) ofrece algortimos de cifrado en modo bloque (CBC) | AC12: Deshabilitar el uso de algoritmos cifrado de bloques (CBC) en el servidor remoto. | AD12: El servidor usa algoritmos de cifrado CBC sobre TLS por lo que está afectado por una vulnerabilidad conocida como Lucky13. Según se ha podido determinar el servidor utiliza cifrados CBC sobre TLS, lo que permitiría a un atacante situado en mitad de las comunicaciones (MiTM) implementar una variante del ataque conocido como Padding de Oracle (POODLE). CVEs Asociados •CVE-2013-0169 | AE12: 44012 | AF12: Fue dado de baja el Lunes 13 de Julio del 2020 | AH12: =IFERROR(VLOOKUP(H12,hoja1!A:A,1,),"N/A") -> N/A
A13: 12 | B13: BSNC | C13: Deloitte | D13: Wep App | E13: BSNC-2019-010 | G13: Web de Proveedores | H13: MAN-647bb2ad | I13: CO-19-MANU-02-AP-007 | J13: Ausencia de Cabecera CSP (Content-security-Policy) | L13: Dismissed | M13: Low | N13: 3.5 | P13: 170.169.33.48 | Q13: confirming.santander.com.co | T13: 43784 | U13: =TODAY()-T13 -> 2425 | V13: =IF(M13="Critical",T13+10,IF(M13="High",T13+30,IF(M13="Bad",T13+30,IF(M13="Medium",T13+90,IF(M13="Warm",T13+90,IF(M13="Low",T13+120,IF(M13="Fair",T13+120,IF(M13="Neutral",T13+120,"")))))))) -> 43904 | W13: =IF(M13="Critical",IF(U13>10,"SLA Vencido","En SLA"),IF(M13="High",IF(U13>30,"SLA Vencido","En SLA"),IF(M13="Bad",IF(U13>30,"SLA Vencido","En SLA"),IF(M13="Medium",IF(U13>90,"SLA Vencido","En SLA"),IF(M13="Warm",IF(U13>90,"SLA Vencido","En SLA"),IF(M13="Low",IF(U13>120,"SLA Vencido","En SLA"),IF(M13="Fair",IF(U13>120,"SLA Vencido","En SLA"),IF(M13="Neutral",IF(U13>120,"SLA Vencido","En SLA"),"Error")))))))) -> SLA Vencido | X13: Waiver | Y13: 1ª Fecha: 21/12/2019 2ª Fecha: 13/04/2020 | Z13: 1ª Fecha: 30/04/2020 2ª Fecha: 30/06/2020 | AA13: 44025 | AB13: se ha identificado la ausencia de la cabecera CSP (Content_Security_Policy) mediante las cabeceras de respuesta http | AC13: Configure el servidor web para devolver la cabecera Content-Security-Policy HTTP. Es recomendable que se establezca la política “default-src ‘self’ para que el contenido provenga del mismo origen del sitio. Un ejemplo de la política sería: Content-Security-Policy: default-src 'self' | AD13: CSP (Content Security Policy) es una capa añadida de seguridad que ayuda a detectar y mitigar determinados tipos de ataques, incluyendo ataques Cross-Site Scripting (XSS) y de inyección de datos. Estos ataques se pueden utilizar para realizar todo tipo de técnicas, desde el robo de datos hasta site defacement, pasando por la distribución de malware. CSP proporciona una serie de cabeceras HTTP estándar que permiten que los propietarios de los sitios web declaren que fuentes de contenido se consideran legitimas para que los puedan usarlas. Por ejemplo, JavaScript, CSS, tramas HTML, fuentes, imágenes y archivos incrustables como applets Java, ActiveX y archivos de audio y vídeo. | AE13: 44012 | AF13: Fue dado de baja el Lunes 13 de Julio del 2020 | AH13: =IFERROR(VLOOKUP(H13,hoja1!A:A,1,),"N/A") -> N/A
A14: 13 | B14: BSNC | C14: Deloitte | D14: Wep App | E14: BSNC-2019-018 | G14: Web de Proveedores | H14: MAN-73a2e327 | I14: CO-19-MANU-01-AP-008 | J14: Fuga de información de rutas internas | L14: Dismissed | M14: Low | N14: 3.2 | P14: 170.169.33.48 | Q14: confirming.santander.com.co | T14: 43609 | U14: =TODAY()-T14 -> 2600 | V14: =IF(M14="Critical",T14+10,IF(M14="High",T14+30,IF(M14="Bad",T14+30,IF(M14="Medium",T14+90,IF(M14="Warm",T14+90,IF(M14="Low",T14+120,IF(M14="Fair",T14+120,IF(M14="Neutral",T14+120,"")))))))) -> 43729 | W14: =IF(M14="Critical",IF(U14>10,"SLA Vencido","En SLA"),IF(M14="High",IF(U14>30,"SLA Vencido","En SLA"),IF(M14="Bad",IF(U14>30,"SLA Vencido","En SLA"),IF(M14="Medium",IF(U14>90,"SLA Vencido","En SLA"),IF(M14="Warm",IF(U14>90,"SLA Vencido","En SLA"),IF(M14="Low",IF(U14>120,"SLA Vencido","En SLA"),IF(M14="Fair",IF(U14>120,"SLA Vencido","En SLA"),IF(M14="Neutral",IF(U14>120,"SLA Vencido","En SLA"),"Error")))))))) -> SLA Vencido | X14: Waiver | Y14: 1ª Fecha: 21/12/2019 2ª Fecha: 13/04/2020 | Z14: 1ª Fecha: 30/04/2020 2ª Fecha: 30/06/2020 | AA14: 44025 | AB14: Se ha detectado que la aplicación devuelve información acerca de rutas internas del sistema de ficheros del servidor. Esta información podría ser utilizada por un atacante con el objetivo de recabar información para ataques futuros. | AC14: Se recomienda evitar que la aplicación devuelva al usuario información relativa al funcionamiento interno del servidor, como pueden ser rutas internas o ubicación de ficheros o directorios dentro del mismo. Para ello, se recomienda modificar la página de error "404 not found". | AD14: Se ha detectado que la aplicación devuelve información acerca de rutas internas del sistema de ficheros del servidor. Esta información podría ser utilizada por un atacante con el objetivo de recabar información para ataques futuros. | AE14: 44012 | AF14: Fue dado de baja el Lunes 13 de Julio del 2020 | AH14: =IFERROR(VLOOKUP(H14,hoja1!A:A,1,),"N/A") -> N/A
A15: 14 | B15: BSNC | C15: Deloitte | D15: Wep App | E15: BSNC-2019-020 | G15: Web de Proveedores | H15: MAN-73a2e326 | I15: CO-19-MANU-01-CO-007 | J15: Suite de cifrado SSL de 64-bit Soportada (SWEET32) | L15: Dismissed | M15: Low | N15: 2.5999999 | P15: 170.169.33.48 | Q15: confirming.santander.com.co | T15: 43609 | U15: =TODAY()-T15 -> 2600 | V15: =IF(M15="Critical",T15+10,IF(M15="High",T15+30,IF(M15="Bad",T15+30,IF(M15="Medium",T15+90,IF(M15="Warm",T15+90,IF(M15="Low",T15+120,IF(M15="Fair",T15+120,IF(M15="Neutral",T15+120,"")))))))) -> 43729 | W15: =IF(M15="Critical",IF(U15>10,"SLA Vencido","En SLA"),IF(M15="High",IF(U15>30,"SLA Vencido","En SLA"),IF(M15="Bad",IF(U15>30,"SLA Vencido","En SLA"),IF(M15="Medium",IF(U15>90,"SLA Vencido","En SLA"),IF(M15="Warm",IF(U15>90,"SLA Vencido","En SLA"),IF(M15="Low",IF(U15>120,"SLA Vencido","En SLA"),IF(M15="Fair",IF(U15>120,"SLA Vencido","En SLA"),IF(M15="Neutral",IF(U15>120,"SLA Vencido","En SLA"),"Error")))))))) -> SLA Vencido | X15: Waiver | Y15: 1ª Fecha: 21/12/2019 2ª Fecha: 13/04/2020 | Z15: 1ª Fecha: 30/04/2020 2ª Fecha: 30/06/2020 | AA15: 44025 | AB15: El activo "confirming.santander.com.co " es vulnerable a SWEET32 | AC15: Se recomienda reconfigurar la aplicación afectada, si es posible, para evitar el uso de todos los cifrados de bloques de 64 bits. Como alternativa, coloque limitaciones en el número de solicitudes que se permiten procesar sobre la misma conexión TLS para mitigar esta vulnerabilidad. | AD15: El servidor admite el uso de un cifrado de bloque con bloques de 64 bits en una o más suites de cifrado. Está afectado por una vulnerabilidad, conocida como SWEET32, debido al uso de cifrados débiles. Un ataque Man in the Middle con recursos suficientes puede explotar esta vulnerabilidad. | AE15: 44012 | AF15: Fue dado de baja el Lunes 13 de Julio del 2020 | AH15: =IFERROR(VLOOKUP(H15,hoja1!A:A,1,),"N/A") -> N/A
A16: 15 | B16: BSNC | C16: Deloitte | D16: Wep App | E16: A2 20190509_2.3.1.c_CO_20200728_N_06 | G16: Confirming & Factoring\Bot | H16: MAN-18af2323 | I16: CO-19-AUTO-02-CO-002 | J16: Uso de librerias desactualizadas | L16: Solved | M16: Medium | N16: 5.5999999 | P16: 64.76.90.137 | Q16: confirming-factoring.santander.com.co | R16: 443 | T16: 43719 | U16: =TODAY()-T16 -> 2490 | V16: =IF(M16="Critical",T16+10,IF(M16="High",T16+30,IF(M16="Bad",T16+30,IF(M16="Medium",T16+90,IF(M16="Warm",T16+90,IF(M16="Low",T16+120,IF(M16="Fair",T16+120,IF(M16="Neutral",T16+120,"")))))))) -> 43809 | W16: =IF(M16="Critical",IF(U16>10,"SLA Vencido","En SLA"),IF(M16="High",IF(U16>30,"SLA Vencido","En SLA"),IF(M16="Bad",IF(U16>30,"SLA Vencido","En SLA"),IF(M16="Medium",IF(U16>90,"SLA Vencido","En SLA"),IF(M16="Warm",IF(U16>90,"SLA Vencido","En SLA"),IF(M16="Low",IF(U16>120,"SLA Vencido","En SLA"),IF(M16="Fair",IF(U16>120,"SLA Vencido","En SLA"),IF(M16="Neutral",IF(U16>120,"SLA Vencido","En SLA"),"Error")))))))) -> SLA Vencido | X16: Waiver | Y16: 1ª Fecha: 28/12/2020 | Z16: 1ª Fecha: 18/12/2020 | AA16: 44089 | AB16: Se encuentra el uso de funciones de Zoom Search Engine 5.0: /factoring/ayuda/zoom_search.js | AC16: Se recomienda utilizar versiones actualizadas del software y/o plataformas tecnológicas utilizadas, en caso de no ser posible aplicar todas las actualizaciones de seguridad publicadas para la versión utilizada. | AD16: El software o plataforma utilizada no se encuentra actualizado a la última versión disponible. Esto implica que podría ser susceptible de poder ser comprometido mediante vulnerabilidades conocidas que pudieran poner en riesgo el activo afectado. | AE16: Sin definir | AF16: Certificada | AG16: Jaime Orlando Vargas Martinez | AH16: =IFERROR(VLOOKUP(H16,hoja1!A:A,1,),"N/A") -> N/A
A17: 16 | B17: BSNC | C17: Deloitte | D17: Wep App | E17: A2 20190509_2.3.1.c_CO_20200728_N_05 | G17: Confirming & Factoring\Bot | H17: MAN-18af2329 | I17: CO-19-AUTO-02-CO-008 | J17: Renegociación segura de SSL iniciada por el cliente | L17: Solved | M17: Medium | N17: 4.3000002 | P17: 64.76.90.137 | Q17: confirming-factoring.santander.com.co | R17: 443 | T17: 43719 | U17: =TODAY()-T17 -> 2490 | V17: =IF(M17="Critical",T17+10,IF(M17="High",T17+30,IF(M17="Bad",T17+30,IF(M17="Medium",T17+90,IF(M17="Warm",T17+90,IF(M17="Low",T17+120,IF(M17="Fair",T17+120,IF(M17="Neutral",T17+120,"")))))))) -> 43809 | W17: =IF(M17="Critical",IF(U17>10,"SLA Vencido","En SLA"),IF(M17="High",IF(U17>30,"SLA Vencido","En SLA"),IF(M17="Bad",IF(U17>30,"SLA Vencido","En SLA"),IF(M17="Medium",IF(U17>90,"SLA Vencido","En SLA"),IF(M17="Warm",IF(U17>90,"SLA Vencido","En SLA"),IF(M17="Low",IF(U17>120,"SLA Vencido","En SLA"),IF(M17="Fair",IF(U17>120,"SLA Vencido","En SLA"),IF(M17="Neutral",IF(U17>120,"SLA Vencido","En SLA"),"Error")))))))) -> SLA Vencido | X17: Waiver | Y17: 1ª Fecha: 28/12/2020 | Z17: 1ª Fecha: 18/12/2020 | AA17: 44181 | AC17: Se recomienda actualizar el servidor web a la última versión, ya que las últimas versiones de Apache y nginx no permiten la renegociación SSL iniciada por el cliente. | AD17: El proceso de negociación del cifrado SSL utiliza significativamente más recursos en el servidor que en el cliente. Si el cliente puede iniciar el proceso de renegociación, un atacante puede hacer que el servidor deje de estar disponible con un ataque de denegación de servicio. | AF17: Certificada | AG17: Jaime Orlando Vargas Martinez | AH17: =IFERROR(VLOOKUP(H17,hoja1!A:A,1,),"N/A") -> N/A
A18: 17 | B18: BSNC | C18: Deloitte | D18: Wep App | E18: A2 20190509_2.3.1.c_CO_20200728_N_03 | G18: Confirming & Factoring\Bot | H18: MAN-647bb2aa | I18: CO-19-MANU-02-AP-004 | J18: Librerías de JavaScript desactualizadas | L18: Solved | M18: Low | N18: 3.5 | P18: 64.76.90.137 | Q18: confirming-factoring.santander.com.co | T18: 43784 | U18: =TODAY()-T18 -> 2425 | V18: =IF(M18="Critical",T18+10,IF(M18="High",T18+30,IF(M18="Bad",T18+30,IF(M18="Medium",T18+90,IF(M18="Warm",T18+90,IF(M18="Low",T18+120,IF(M18="Fair",T18+120,IF(M18="Neutral",T18+120,"")))))))) -> 43904 | W18: =IF(M18="Critical",IF(U18>10,"SLA Vencido","En SLA"),IF(M18="High",IF(U18>30,"SLA Vencido","En SLA"),IF(M18="Bad",IF(U18>30,"SLA Vencido","En SLA"),IF(M18="Medium",IF(U18>90,"SLA Vencido","En SLA"),IF(M18="Warm",IF(U18>90,"SLA Vencido","En SLA"),IF(M18="Low",IF(U18>120,"SLA Vencido","En SLA"),IF(M18="Fair",IF(U18>120,"SLA Vencido","En SLA"),IF(M18="Neutral",IF(U18>120,"SLA Vencido","En SLA"),"Error")))))))) -> SLA Vencido | X18: Waiver | Y18: 1ª Fecha: 28/12/2020 | Z18: 1ª Fecha: 18/12/2020 | AA18: 44235 | AB18: Durante la auditoria se ha identificado la librería de JavaScript jQuery en su versión 1.3.2 la cual contiene vulnerabilidades, con CVE asociado, conocidas como:  CVE-2019-11358  CVE-2016-10707  CVE-2016-7103  CVE-2015-9251  CVE-2014-6071  CVE-2012-6708  CVE-2011-4969  CVE-2007-2379 Adicionalmente, se ha identificado el Framework de JavaScript “Prototype” en su versión 1.6.0.3 la cual contiene vulnerabilidades, con CVE asociado, conocidas como:  CVE-2008-7220  CVE-2007-2383 | AC18: Se recomienda analizar la posibilidad de actualizar la librería afectada a la última versión disponible. En concreto:  Prototype. Última versión estable 1.7.3 (http://prototypejs.org/)  jQuery. Última versión estable 3.4.1 (https://jquery.com/download/) Adicionalmente se recomienda realizar el monitoreo regular de las actualizaciones de las librerías en uso para todas las aplicaciones y asegurarse de instalarlas en un tiempo prudencial. | AD18: Un individuo malicioso podría comprometer con mayor facilidad las librerías afectadas, ya que las versiones observadas poseen vulnerabilidades y/o debilidades de seguridad previamente reportadas. Las vulnerabilidades mencionadas son de conocimiento público y los detalles de las mismas se encuentran disponibles. En consecuencia, un individuo malicioso podría intentar explotarlas para comprometer a los usuarios de la aplicación. | AE18: 44219 | AF18: Certificada | AG18: Jaime Orlando Vargas Martinez | AH18: =IFERROR(VLOOKUP(H18,hoja1!A:A,1,),"N/A") -> N/A
A19: 18 | B19: BSNC | C19: Deloitte | D19: Wep App | E19: A2 20190509_2.3.1.c_CO_20200728_N_04 | G19: Confirming & Factoring\Bot | H19: MAN-647bb2ab | I19: CO-19-MANU-02-AP-005 | J19: Errores no controlados | L19: Solved | M19: Low | N19: 3.5 | P19: 64.76.90.137 | Q19: confirming-factoring.santander.com.co | T19: 43784 | U19: =TODAY()-T19 -> 2425 | V19: =IF(M19="Critical",T19+10,IF(M19="High",T19+30,IF(M19="Bad",T19+30,IF(M19="Medium",T19+90,IF(M19="Warm",T19+90,IF(M19="Low",T19+120,IF(M19="Fair",T19+120,IF(M19="Neutral",T19+120,"")))))))) -> 43904 | W19: =IF(M19="Critical",IF(U19>10,"SLA Vencido","En SLA"),IF(M19="High",IF(U19>30,"SLA Vencido","En SLA"),IF(M19="Bad",IF(U19>30,"SLA Vencido","En SLA"),IF(M19="Medium",IF(U19>90,"SLA Vencido","En SLA"),IF(M19="Warm",IF(U19>90,"SLA Vencido","En SLA"),IF(M19="Low",IF(U19>120,"SLA Vencido","En SLA"),IF(M19="Fair",IF(U19>120,"SLA Vencido","En SLA"),IF(M19="Neutral",IF(U19>120,"SLA Vencido","En SLA"),"Error")))))))) -> SLA Vencido | X19: Waiver | Y19: 1ª Fecha: 28/12/2020 | Z19: 1ª Fecha: 18/12/2020 | AA19: 44089 | AB19: se ha identificado que, al modificar la petición original, el servidor responde con un error, mostrando una función interna de la aplicación. En concreto:  https://confirming-factoring.santander.com.co  Menú: Consultar ejecuciones Generales /Procesos Automáticos Al realizar una búsqueda, se para la petición mediante un proxy intermedio (BurpSuite) y se modifica el campo “formSearchCiclo%3Afecha_desdeField%3Aecha_inicioInputCurrentDate” introduciendo un valor no esperado por la aplicación, por ejemplo, una comilla simple, la aplicación responde mostrando información interna de la aplicación, en concreto una función de Java | AC19: Se deben controlar todas las entradas o valores que el aplicativo recibe por parte del cliente, y realizar un tratamiento seguro de sus valores evitando proporcionar información útil a un posible atacante. Adicionalmente para no proporcionar información al atacante se recomienda personalizar las páginas de error para que no sean descriptivas. | AD19: El servidor Web al recibir una petición no esperada reacciona mostrando una página de error que revela información sensible de la plataforma subyacente. Con esta información un atacante puede realizar ataques dirigidos con mayor criticidad y éxito sobre los sistemas y aplicaciones. | AE19: Sin definir | AF19: Certificada | AG19: Jaime Orlando Vargas Martinez | AH19: =IFERROR(VLOOKUP(H19,hoja1!A:A,1,),"N/A") -> N/A
A20: 19 | B20: BSNC | C20: Deloitte | D20: Wep App | E20: BSNC-2019-101 | G20: Portal Web | H20: MAN-4c3ceca0 | I20: CO-19-MANU-01-VE-009 | J20: Librerias de Javascript vulnerables | L20: Solved | M20: Critical | N20: 7.6999998 | P20: 170.169.33.93 | Q20: www.santander.com.co | R20: 443 | T20: 43697 | U20: =TODAY()-T20 -> 2512 | V20: =IF(M20="Critical",T20+10,IF(M20="High",T20+30,IF(M20="Bad",T20+30,IF(M20="Medium",T20+90,IF(M20="Warm",T20+90,IF(M20="Low",T20+120,IF(M20="Fair",T20+120,IF(M20="Neutral",T20+120,"")))))))) -> 43707 | W20: =IF(M20="Critical",IF(U20>10,"SLA Vencido","En SLA"),IF(M20="High",IF(U20>30,"SLA Vencido","En SLA"),IF(M20="Bad",IF(U20>30,"SLA Vencido","En SLA"),IF(M20="Medium",IF(U20>90,"SLA Vencido","En SLA"),IF(M20="Warm",IF(U20>90,"SLA Vencido","En SLA"),IF(M20="Low",IF(U20>120,"SLA Vencido","En SLA"),IF(M20="Fair",IF(U20>120,"SLA Vencido","En SLA"),IF(M20="Neutral",IF(U20>120,"SLA Vencido","En SLA"),"Error")))))))) -> SLA Vencido | X20: Waiver | Y20: 1ª Fecha: 2ª Fecha: | Z20: 1ª Fecha: 2ª Fecha:23/08/2020 | AA20: 44117 | AB20: La confirmación del uso de una versión vulnerable de la biblioteca javascript Https://www.santander.com.co/js/jquery-1.10,2.min.js Version: Jquery 1.10.2 | AC20: Actualizar las librerias de JavaScript a la última versión | AD20: Se detectaron bibliotecas Java Script Jquery obsoletas, las cuales pueden ser explotadas mediante secuencias de comandos entre sitios (XSS). | AE20: 44119 | AF20: Certificada | AG20: Jaime Orlando Vargas Martinez | AH20: =IFERROR(VLOOKUP(H20,hoja1!A:A,1,),"N/A") -> N/A
A21: 20 | B21: BSNC | C21: Deloitte | D21: Wep App | E21: A2 20190509_2.3.1.c_CO_20200611_R | F21: BSNC-2019-102 | G21: Portal Web | H21: MAN-4c3ced42 | I21: CO-19-MANU-01-VE-010 | J21: Librerias de Bootstrap vulnerables | L21: Solved | M21: Critical | N21: 7.6999998 | P21: 170.169.33.93 | Q21: www.santander.com.co | R21: 443 | T21: 43700 | U21: =TODAY()-T21 -> 2509 | V21: =IF(M21="Critical",T21+10,IF(M21="High",T21+30,IF(M21="Bad",T21+30,IF(M21="Medium",T21+90,IF(M21="Warm",T21+90,IF(M21="Low",T21+120,IF(M21="Fair",T21+120,IF(M21="Neutral",T21+120,"")))))))) -> 43710 | W21: =IF(M21="Critical",IF(U21>10,"SLA Vencido","En SLA"),IF(M21="High",IF(U21>30,"SLA Vencido","En SLA"),IF(M21="Bad",IF(U21>30,"SLA Vencido","En SLA"),IF(M21="Medium",IF(U21>90,"SLA Vencido","En SLA"),IF(M21="Warm",IF(U21>90,"SLA Vencido","En SLA"),IF(M21="Low",IF(U21>120,"SLA Vencido","En SLA"),IF(M21="Fair",IF(U21>120,"SLA Vencido","En SLA"),IF(M21="Neutral",IF(U21>120,"SLA Vencido","En SLA"),"Error")))))))) -> SLA Vencido | X21: Waiver | Y21: 1ª Fecha: 17/12/2019 2ª Fecha: 11/06/2020 | Z21: 1ª Fecha: 30/04/2020 2ª Fecha: 04/09/2020 | AA21: 44071 | AB21: La confirmación del uso de una versión vulnerable de la biblioteca javascript https://www.santander.com.co/js/bootstrap.min.js Versión:Bootstrap 3.0.2 | AC21: Actualizar las librerias de Bootstrap a la última versión | AD21: Se detectaron bibliotecas Bootstrap obsoletas, las cuales pueden ser explotadas mediante secuencias de comandos entre sitios (XSS). Esto puede conducir a diferentes problemas para los usuarios de la aplicación. | AE21: 44078 | AF21: Certificada | AG21: Jaime Orlando Vargas Martinez | AH21: =IFERROR(VLOOKUP(H21,hoja1!A:A,1,),"N/A") -> N/A
A22: 21 | B22: BSNC | C22: Deloitte | D22: Wep App | G22: Portal Web | H22: MAN-647bb2a7 | I22: CO-19-MANU-02-AP-001 | J22: Información sensible en Metadatos de Ficheros | L22: Solved | M22: Medium | N22: 5 | P22: 170.169.33.93 | Q22: www.santander.com.co | T22: 43784 | U22: =TODAY()-T22 -> 2425 | V22: =IF(M22="Critical",T22+10,IF(M22="High",T22+30,IF(M22="Bad",T22+30,IF(M22="Medium",T22+90,IF(M22="Warm",T22+90,IF(M22="Low",T22+120,IF(M22="Fair",T22+120,IF(M22="Neutral",T22+120,"")))))))) -> 43874 | W22: =IF(M22="Critical",IF(U22>10,"SLA Vencido","En SLA"),IF(M22="High",IF(U22>30,"SLA Vencido","En SLA"),IF(M22="Bad",IF(U22>30,"SLA Vencido","En SLA"),IF(M22="Medium",IF(U22>90,"SLA Vencido","En SLA"),IF(M22="Warm",IF(U22>90,"SLA Vencido","En SLA"),IF(M22="Low",IF(U22>120,"SLA Vencido","En SLA"),IF(M22="Fair",IF(U22>120,"SLA Vencido","En SLA"),IF(M22="Neutral",IF(U22>120,"SLA Vencido","En SLA"),"Error")))))))) -> SLA Vencido | AA22: 44014 | AB22: Se ha evidenciado una serie de nombres de usuarios en los metadatos de los ficheros PDF, los cuales se han identificado dentro de las páginas webs del alcance. | AC22: Se recomienda eliminar toda la información contenida en los metadatos de los documentos generados y/o publicados en la aplicación. Adicionalmente, se recomienda implementar un procedimiento para controlar los documentos a publicar para garantizar que los mismos no contengan información sensible de la organización en sus metadatos. | AD22: Los metadatos de un fichero o documento pueden revelar tanta o más información que el contenido de las comunicaciones. Las fugas de información sensible son realizadas, en numerosas ocasiones, a través de los metadatos de los ficheros publicados, que desvelan entre otros datos, usuarios o nombres de personas de la empresa. | AE22: 44036 | AF22: Certificada | AG22: Jaime Orlando Vargas Martinez | AH22: =IFERROR(VLOOKUP(H22,hoja1!A:A,1,),"N/A") -> N/A
A23: 22 | B23: BSNC | C23: Deloitte | D23: Wep App | E23: BSNC-2020-002 | G23: Portal Web | H23: MAN-18af232a | I23: CO-19-AUTO-02-CO-007 | J23: Renegociación segura de SSL iniciada por el cliente | L23: Dismissed | M23: Medium | N23: 4.3000002 | P23: 170.169.33.93 | Q23: www.santander.com.co | R23: 443 | T23: 43719 | U23: =TODAY()-T23 -> 2490 | V23: =IF(M23="Critical",T23+10,IF(M23="High",T23+30,IF(M23="Bad",T23+30,IF(M23="Medium",T23+90,IF(M23="Warm",T23+90,IF(M23="Low",T23+120,IF(M23="Fair",T23+120,IF(M23="Neutral",T23+120,"")))))))) -> 43809 | W23: =IF(M23="Critical",IF(U23>10,"SLA Vencido","En SLA"),IF(M23="High",IF(U23>30,"SLA Vencido","En SLA"),IF(M23="Bad",IF(U23>30,"SLA Vencido","En SLA"),IF(M23="Medium",IF(U23>90,"SLA Vencido","En SLA"),IF(M23="Warm",IF(U23>90,"SLA Vencido","En SLA"),IF(M23="Low",IF(U23>120,"SLA Vencido","En SLA"),IF(M23="Fair",IF(U23>120,"SLA Vencido","En SLA"),IF(M23="Neutral",IF(U23>120,"SLA Vencido","En SLA"),"Error")))))))) -> SLA Vencido | AA23: 43917 | AC23: Se recomienda actualizar el servidor web a la última versión, ya que las últimas versiones de Apache y nginx no permiten la renegociación SSL iniciada por el cliente. | AD23: El proceso de negociación del cifrado SSL utiliza significativamente más recursos en el servidor que en el cliente. Si el cliente puede iniciar el proceso de renegociación, un atacante puede hacer que el servidor deje de estar disponible con un ataque de denegación de servicio. | AF23: Corresponde a un Falso Positivo | AG23: Jaime Orlando Vargas Martinez | AH23: =IFERROR(VLOOKUP(H23,hoja1!A:A,1,),"N/A") -> N/A
A24: 23 | B24: BSNC | C24: Deloitte | D24: Wep App | E24: A2 20190509_2.3.1.c_CO_20200612_N_08 | G24: Portal Web | H24: MAN-647bb2ac | I24: CO-19-MANU-02-AP-006 | J24: Métodos HTTP no seguros permitidos | L24: Solved | M24: Low | N24: 3.5 | P24: 170.169.33.93 | Q24: www.santander.com.co | T24: 43784 | U24: =TODAY()-T24 -> 2425 | V24: =IF(M24="Critical",T24+10,IF(M24="High",T24+30,IF(M24="Bad",T24+30,IF(M24="Medium",T24+90,IF(M24="Warm",T24+90,IF(M24="Low",T24+120,IF(M24="Fair",T24+120,IF(M24="Neutral",T24+120,"")))))))) -> 43904 | W24: =IF(M24="Critical",IF(U24>10,"SLA Vencido","En SLA"),IF(M24="High",IF(U24>30,"SLA Vencido","En SLA"),IF(M24="Bad",IF(U24>30,"SLA Vencido","En SLA"),IF(M24="Medium",IF(U24>90,"SLA Vencido","En SLA"),IF(M24="Warm",IF(U24>90,"SLA Vencido","En SLA"),IF(M24="Low",IF(U24>120,"SLA Vencido","En SLA"),IF(M24="Fair",IF(U24>120,"SLA Vencido","En SLA"),IF(M24="Neutral",IF(U24>120,"SLA Vencido","En SLA"),"Error")))))))) -> SLA Vencido | X24: Waiver | Y24: 1ª Fecha: 12/06/2020 | Z24: 2ª Fecha: 13/11/2020 | AA24: 44117 | AB24: se han identificado métodos http los cuales no son seguros y podrían suponer un riesgo para el servidor, en concreto, se han detectado los métodos: PUT, DELETE, TRACE y PATCH. | AC24: Se recomienda analizar la posibilidad de evaluar si el método HTTP extendido identificado es requerido por razones de negocio y deshabilitarlo en caso de no ser requerido. Asimismo, se recomienda analizar la posibilidad de revisar los estándares de configuración de los sistemas, para asegurar que métodos potencialmente peligrosos se encuentren deshabilitados y asegurar su consistencia en toda la organización. | AD24: Los servidores Web utilizan ciertos métodos o funciones propias del protocolo HTTP para funcionar siendo los más utilizados GET, POST y HEAD. Como resultado del análisis de los servicios Web internos se ha detectado que los recursos afectados permiten utilizar métodos HTTP adicionales (OPTIONS, TRACE, GET, HEAD, DELETE, PUT, POST, COPY, MOVE, MKCOL, PROPFIND, PROPPATCH, LOCK, UNLOCK, SEARCH) los cuales podrían no ser requeridos debilitando la seguridad de dichos servicios Web. | AE24: 44148 | AF24: Certificada | AG24: Jaime Orlando Vargas Martinez | AH24: =IFERROR(VLOOKUP(H24,hoja1!A:A,1,),"N/A") -> N/A
A25: 24 | B25: BSNC | C25: Deloitte | D25: Wep App | E25: BSNC-2020-001 | G25: Portal Web | H25: MAN-73a2e325 | I25: CO-19-MANU-01-AP-006 | J25: Fuga de información de aplicación y versión | L25: Solved | M25: Low | N25: 3.2 | P25: 170.169.33.93 | Q25: www.santander.com.co | T25: 43609 | U25: =TODAY()-T25 -> 2600 | V25: =IF(M25="Critical",T25+10,IF(M25="High",T25+30,IF(M25="Bad",T25+30,IF(M25="Medium",T25+90,IF(M25="Warm",T25+90,IF(M25="Low",T25+120,IF(M25="Fair",T25+120,IF(M25="Neutral",T25+120,"")))))))) -> 43729 | W25: =IF(M25="Critical",IF(U25>10,"SLA Vencido","En SLA"),IF(M25="High",IF(U25>30,"SLA Vencido","En SLA"),IF(M25="Bad",IF(U25>30,"SLA Vencido","En SLA"),IF(M25="Medium",IF(U25>90,"SLA Vencido","En SLA"),IF(M25="Warm",IF(U25>90,"SLA Vencido","En SLA"),IF(M25="Low",IF(U25>120,"SLA Vencido","En SLA"),IF(M25="Fair",IF(U25>120,"SLA Vencido","En SLA"),IF(M25="Neutral",IF(U25>120,"SLA Vencido","En SLA"),"Error")))))))) -> SLA Vencido | AA25: 43908 | AB25: Durante las pruebas realizadas, se ha comprobado que la página de error "404 not found" por defecto de Tomcat muestra información interna acerca de la aplicación utilizada. | AC25: Se recomienda modificar la página por defecto "404 not found" para evitar que la aplicación devuelva al usuario información relativa a la naturaleza y versión de la misma. | AD25: Se ha detectado que la aplicación devuelve información acerca de la versión y aplicación utilizadas. Esta información podría ser utilizada por un atacante con el objetivo de recabar información para ataques futuros. | AF25: Certificada | AG25: Jaime Orlando Vargas Martinez | AH25: =IFERROR(VLOOKUP(H25,hoja1!A:A,1,),"N/A") -> N/A
A26: 25 | B26: BSNC | C26: Deloitte | D26: Wep App | E26: BSNC-2020-003 | G26: Portal Web | H26: MAN-18af232d | I26: CO-19-AUTO-02-CO-010 | J26: Ausencia de HTTP Strict Transport Security (HSTS) | L26: Solved | M26: Low | N26: 3.0999999 | P26: 170.169.33.93 | Q26: www.santander.com.co | R26: 443 | T26: 43719 | U26: =TODAY()-T26 -> 2490 | V26: =IF(M26="Critical",T26+10,IF(M26="High",T26+30,IF(M26="Bad",T26+30,IF(M26="Medium",T26+90,IF(M26="Warm",T26+90,IF(M26="Low",T26+120,IF(M26="Fair",T26+120,IF(M26="Neutral",T26+120,"")))))))) -> 43839 | W26: =IF(M26="Critical",IF(U26>10,"SLA Vencido","En SLA"),IF(M26="High",IF(U26>30,"SLA Vencido","En SLA"),IF(M26="Bad",IF(U26>30,"SLA Vencido","En SLA"),IF(M26="Medium",IF(U26>90,"SLA Vencido","En SLA"),IF(M26="Warm",IF(U26>90,"SLA Vencido","En SLA"),IF(M26="Low",IF(U26>120,"SLA Vencido","En SLA"),IF(M26="Fair",IF(U26>120,"SLA Vencido","En SLA"),IF(M26="Neutral",IF(U26>120,"SLA Vencido","En SLA"),"Error")))))))) -> SLA Vencido | AA26: 43921 | AB26: Las url afectadas son: /js/bootstrap-paginator.js /js/cookiesUtils.js /recursos/imagenes/home_142.jpg /recursos/imagenes/home_63.jpg | AC26: Se recomienda configurar el servidor remoto para que en las cabeceras de respuesta se incluya la cabecera HSTS incluyendo un período de validez estimado de la política en el propio navegador. | AD26: La política HSTS o HTTP Strict Transport Security es un mecanismo soportado por los principales servidores web –Apache, NGNIX- y la mayoría de navegadores, que reduce las posibilidades de que un atacante pueda interceptar nuestras comunicaciones y recopilar cookies y datos similares intercambiados durante la sesión. El estándar permite que el servidor y el navegador web interactúen de manera más fiable, empleando protocolos de transporte cifrados como TSL/SSL. Así, es capaz de acabar con variados ataques de red y también con algunos errores cometidos por los desarrolladores de los distintos sites (por ejemplo, el uso de conexiones no seguras para descargar recursos de la web). De esta manera y al margen de determinar cómo deben actuar el navegador y el servidor, HSTS incorpora una cabecera HSTS (Strict-Transport-Security), que fuerza a utilizar un canal cifrado, HTTPS, para la comunicación entre el navegador del usuario y el servidor. A partir del momento en el que el navegador recibe una cabecera HSTS en las cabeceras de respuesta del servidor, todas las peticiones a este dominio y subdominios serán realizadas mediante HTTPS. Asimismo, las cabeceras HSTS, quedarán almacenadas en el navegador (en forma de lista), algo que se aplicará durante un tiempo determinado que se establece en la propia cabecera de respuesta. | AF26: Certificada | AG26: Jaime Orlando Vargas Martinez | AH26: =IFERROR(VLOOKUP(H26,hoja1!A:A,1,),"N/A") -> N/A
A27: 26 | B27: BSNC | C27: Qualys | D27: Wep App | E27: BSNC-2020-004 | G27: Web de Proveedores | H27: QA-1701663040 | J27: SSL/TLS Server supports TLSv1.0 | L27: Dismissed | M27: Medium | N27: Vendor | P27: 170.169.33.48 | Q27: confirming.santander.com.co | R27: 443 | S27: TCP | T27: 43816 | U27: =TODAY()-T27 -> 2393 | V27: =IF(M27="Critical",T27+10,IF(M27="High",T27+30,IF(M27="Bad",T27+30,IF(M27="Medium",T27+90,IF(M27="Warm",T27+90,IF(M27="Low",T27+120,IF(M27="Fair",T27+120,IF(M27="Neutral",T27+120,"")))))))) -> 43906 | W27: =IF(M27="Critical",IF(U27>10,"SLA Vencido","En SLA"),IF(M27="High",IF(U27>30,"SLA Vencido","En SLA"),IF(M27="Bad",IF(U27>30,"SLA Vencido","En SLA"),IF(M27="Medium",IF(U27>90,"SLA Vencido","En SLA"),IF(M27="Warm",IF(U27>90,"SLA Vencido","En SLA"),IF(M27="Low",IF(U27>120,"SLA Vencido","En SLA"),IF(M27="Fair",IF(U27>120,"SLA Vencido","En SLA"),IF(M27="Neutral",IF(U27>120,"SLA Vencido","En SLA"),"Error")))))))) -> SLA Vencido | X27: Waiver | Y27: 1ª Fecha: 2ª Fecha: | Z27: 1ª Fecha: 2ª Fecha: | AA27: 44025 | AC27: Deshabilite el uso del protocolo TLSv1.0 a favor de un protocolo criptográficamente más fuerte como TLSv1.2. Los siguientes comandos de openssl se pueden usar para hacer una prueba manual: openssl s_client -connect ip: puerto -tls1 Si la prueba es exitosa, entonces el objetivo | AD27: Un atacante puede explotar defectos criptográficos para realizar ataques de tipo intermediario o para descifrar comunicaciones. <P> Por ejemplo: un atacante podría forzar una degradación del protocolo TLS al antiguo protocolo SSLv3.0 y explotar el POODLE vulnerabi | AE27: 44012 | AF27: Fue dado de baja el Lunes 13 de Julio del 2020 | AH27: =IFERROR(VLOOKUP(H27,hoja1!A:A,1,),"N/A") -> N/A
A28: 27 | B28: BSNC | C28: Qualys | D28: Wep App | G28: Confirming & Factoring\Bot | H28: QA-94188246370 | J28: SSL Certificate - Subject Common Name Does Not Match Server FQDN | L28: Dismissed | M28: Medium | N28: Vendor | P28: 94188208248 | Q28: confirming-factoring.santander.com.co | R28: 443 | S28: TCP | T28: 43816 | U28: =TODAY()-T28 -> 2393 | V28: =IF(M28="Critical",T28+10,IF(M28="High",T28+30,IF(M28="Bad",T28+30,IF(M28="Medium",T28+90,IF(M28="Warm",T28+90,IF(M28="Low",T28+120,IF(M28="Fair",T28+120,IF(M28="Neutral",T28+120,"")))))))) -> 43906 | W28: =IF(M28="Critical",IF(U28>10,"SLA Vencido","En SLA"),IF(M28="High",IF(U28>30,"SLA Vencido","En SLA"),IF(M28="Bad",IF(U28>30,"SLA Vencido","En SLA"),IF(M28="Medium",IF(U28>90,"SLA Vencido","En SLA"),IF(M28="Warm",IF(U28>90,"SLA Vencido","En SLA"),IF(M28="Low",IF(U28>120,"SLA Vencido","En SLA"),IF(M28="Fair",IF(U28>120,"SLA Vencido","En SLA"),IF(M28="Neutral",IF(U28>120,"SLA Vencido","En SLA"),"Error")))))))) -> SLA Vencido | AB28: Vulnerabilidad presente, debido a que el certificado presente por IP no coincide con el del FQDN (confirming-factoring.santander.com.co), por este motivo se confirma la vulnerabilidad, que conllevaría a la posible situación de cifrado sin autenticación | AC28: Instale un certificado de servidor cuyo Asunto commonName o subjectAltName coincida con el FQDN del servidor. | AD28: Un atacante man-in-the-middle puede explotar esta vulnerabilidad junto con un ataque de envenenamiento de caché DNS para atraer al cliente a otro servidor y luego robar toda la comunicación de cifrado. | AF28: Corresponde a un Falso Positivo | AG28: Jaime Orlando Vargas Martinez | AH28: =IFERROR(VLOOKUP(H28,hoja1!A:A,1,),"N/A") -> N/A
A29: 28 | B29: BSNC | C29: Qualys | D29: Wep App | G29: Confirming & Factoring\Bot | H29: QA-94188219979 | J29: HTTP Security Header Not Detected | L29: Solved | M29: Medium | N29: Vendor | P29: 94188208248 | Q29: confirming-factoring.santander.com.co | R29: 443 | S29: TCP | T29: 43816 | U29: =TODAY()-T29 -> 2393 | V29: =IF(M29="Critical",T29+10,IF(M29="High",T29+30,IF(M29="Bad",T29+30,IF(M29="Medium",T29+90,IF(M29="Warm",T29+90,IF(M29="Low",T29+120,IF(M29="Fair",T29+120,IF(M29="Neutral",T29+120,"")))))))) -> 43906 | W29: =IF(M29="Critical",IF(U29>10,"SLA Vencido","En SLA"),IF(M29="High",IF(U29>30,"SLA Vencido","En SLA"),IF(M29="Bad",IF(U29>30,"SLA Vencido","En SLA"),IF(M29="Medium",IF(U29>90,"SLA Vencido","En SLA"),IF(M29="Warm",IF(U29>90,"SLA Vencido","En SLA"),IF(M29="Low",IF(U29>120,"SLA Vencido","En SLA"),IF(M29="Fair",IF(U29>120,"SLA Vencido","En SLA"),IF(M29="Neutral",IF(U29>120,"SLA Vencido","En SLA"),"Error")))))))) -> SLA Vencido | AA29: 43934 | AC29: <B> Nota: </B> Para depurar mejor los resultados de este QID, se solicita que los clientes ejecuten comandos para simular la siguiente funcionalidad: curl -lkL --verbose. <P> CWE-693: Falla del mecanismo de protección menciona lo siguiente: el producto no | AD29: Dependiendo de la vulnerabilidad que se explota, un atacante remoto no autenticado podría realizar scripts de sitios, clickjacking o ataques de detección de tipo MIME. | AF29: Certificada | AG29: Jaime Orlando Vargas Martinez | AH29: =IFERROR(VLOOKUP(H29,hoja1!A:A,1,),"N/A") -> N/A
A30: 29 | B30: BSNC | C30: Task Force | D30: Telecomunicaciones | G30: Internet invitados Backup Santander (Wifi Backup) | J30: SSL Certificate Not Signed By A Trusted Authority | K30: CWE-296: Improper Following of Chain of Trust for Certificate Validation | L30: Solved | M30: Medium | P30: 181.48.20.105 | R30: 443 | S30: TCP | T30: 43812 | U30: =TODAY()-T30 -> 2397 | V30: =IF(M30="Critical",T30+10,IF(M30="High",T30+30,IF(M30="Bad",T30+30,IF(M30="Medium",T30+90,IF(M30="Warm",T30+90,IF(M30="Low",T30+120,IF(M30="Fair",T30+120,IF(M30="Neutral",T30+120,"")))))))) -> 43902 | W30: =IF(M30="Critical",IF(U30>10,"SLA Vencido","En SLA"),IF(M30="High",IF(U30>30,"SLA Vencido","En SLA"),IF(M30="Bad",IF(U30>30,"SLA Vencido","En SLA"),IF(M30="Medium",IF(U30>90,"SLA Vencido","En SLA"),IF(M30="Warm",IF(U30>90,"SLA Vencido","En SLA"),IF(M30="Low",IF(U30>120,"SLA Vencido","En SLA"),IF(M30="Fair",IF(U30>120,"SLA Vencido","En SLA"),IF(M30="Neutral",IF(U30>120,"SLA Vencido","En SLA"),"Error")))))))) -> SLA Vencido | AA30: 43969 | AB30: The following certificate was part of the certificate chain sent by the remote host, but it has expired : Subject : 2.5.4.41=AR161-Self-Signed-Certificate-21500102122SHB600935 Not After : Apr 02 00:00:00 2010 GMT The following certificate was at the top of the certificate chain sent by the remote host, but it is signed by an unknown certificate authority : Subject : 2.5.4.41=AR161-Self-Signed-Certificate-21500102122SHB600935 Issuer : 2.5.4.41=AR161-Self-Signed-Certificate-21500102122SHB600935 | AC30: Cisco recommends that SSL services always use certificates signed by an authority that clients belonging to normal system users will trust. The vendor for each supported client will be able to provide an up-to-date list of certificate authorities who are trusted by default. One of these will be required to sign the certificate for each affected service. | AF30: Certificada | AH30: =IFERROR(VLOOKUP(H30,hoja1!A:A,1,),"N/A") -> N/A
A31: 30 | B31: BSNC | C31: Task Force | D31: Telecomunicaciones | G31: Internet invitados Backup Santander (Wifi Backup) | J31: SSL Certificate Not Signed By A Trusted Authority | K31: CWE-296: Improper Following of Chain of Trust for Certificate Validation | L31: Solved | M31: Medium | P31: 181.48.20.104 | R31: 443 | S31: TCP | T31: 43812 | U31: =TODAY()-T31 -> 2397 | V31: =IF(M31="Critical",T31+10,IF(M31="High",T31+30,IF(M31="Bad",T31+30,IF(M31="Medium",T31+90,IF(M31="Warm",T31+90,IF(M31="Low",T31+120,IF(M31="Fair",T31+120,IF(M31="Neutral",T31+120,"")))))))) -> 43902 | W31: =IF(M31="Critical",IF(U31>10,"SLA Vencido","En SLA"),IF(M31="High",IF(U31>30,"SLA Vencido","En SLA"),IF(M31="Bad",IF(U31>30,"SLA Vencido","En SLA"),IF(M31="Medium",IF(U31>90,"SLA Vencido","En SLA"),IF(M31="Warm",IF(U31>90,"SLA Vencido","En SLA"),IF(M31="Low",IF(U31>120,"SLA Vencido","En SLA"),IF(M31="Fair",IF(U31>120,"SLA Vencido","En SLA"),IF(M31="Neutral",IF(U31>120,"SLA Vencido","En SLA"),"Error")))))))) -> SLA Vencido | AA31: 43969 | AB31: The following certificate was part of the certificate chain sent by the remote host, but it has expired : Subject : 2.5.4.41=AR161-Self-Signed-Certificate- 186021MISC : Banco Santander (PID 894366) IR Complementary Pen Test 25 CISCO RESTRICTED 21500102122SHB600935 Not After : Apr 02 00:00:00 2010 GMT The following certificate was at the top of the certificate chain sent by the remote host, but it is signed by an unknown certificate authority : Subject : 2.5.4.41=AR161-Self-Signed-Certificate-21500102122SHB600935 Issuer : 2.5.4.41=AR161-Self-Signed-Certificate-21500102122SHB600935 | AC31: Cisco recommends that SSL services always use certificates signed by an authority that clients belonging to normal system users will trust. The vendor for each supported client will be able to provide an up-to-date list of certificate authorities who are trusted by default. One of these will be required to sign the certificate for each affected service. | AF31: Certificada | AH31: =IFERROR(VLOOKUP(H31,hoja1!A:A,1,),"N/A") -> N/A
